<?xml version="1.0" ?>
<!-- =================================================================================== -->
<!-- |    This document was autogenerated by xacro from src/lexx_auto_launch/urdf/v5.urdf | -->
<!-- |    EDITING THIS FILE BY HAND IS NOT RECOMMENDED                                 | -->
<!-- =================================================================================== -->
<robot name="v5_robot">
  <material name="red">
    <color rgba="1.0 0.0 0.0 1.0"/>
  </material>
  <material name="gray">
    <color rgba="0.5 0.5 0.5 1.0"/>
  </material>
  <material name="body_gray">
    <color rgba="0.5 0.5 0.5 0.5"/>
  </material>
  <material name="blue">
    <color rgba="0.0 0.0 1.0 1.0"/>
  </material>
  <material name="green">
    <color rgba="0.0 1.0 0.0 1.0"/>
  </material>
  <material name="magenta">
    <color rgba="1.0 0.0 1.0 1.0"/>
  </material>
  <link name="base_link"/>
  <joint name="body_joint" type="fixed">
    <parent link="base_link"/>
    <child link="body_link"/>
    <origin rpy="0 0 0" xyz="0 0 0"/>
  </joint>
  <link name="body_link">
    <inertial>
      <origin rpy="0 0 0" xyz="0 0 0.14400000000000002"/>
      <mass value="60.0"/>
      <inertia ixx="0.001" ixy="0.0" ixz="0.0" iyy="0.001" iyz="0.0" izz="0.001"/>
    </inertial>
    <visual>
      <origin rpy="0 0 0" xyz="0 0 0.14400000000000002"/>
      <geometry>
        <box size="0.695 0.622 0.228"/>
      </geometry>
      <material name="body_gray"/>
    </visual>
    <collision>
      <origin rpy="0 0 0" xyz="0 0 0.14400000000000002"/>
      <geometry>
        <box size="0.695 0.622 0.228"/>
      </geometry>
    </collision>
  </link>
  <joint name="left_wheel_joint" type="continuous">
    <origin rpy="-1.5707963267948966 0 0" xyz="0 0.28485 0.1016"/>
    <parent link="base_link"/>
    <child link="left_wheel_link"/>
    <axis xyz="0 0 1"/>
    <limit effort="20.4" velocity="20.0"/>
    <dynamics damping="0.1"/>
  </joint>
  <transmission name="left_wheel_trans" type="SimpleTransmission">
    <type>transmission_interface/SimpleTransmission</type>
    <actuator name="left_wheel_motor">
      <mechanicalReduction>1</mechanicalReduction>
    </actuator>
    <joint name="left_wheel_joint">
      <hardwareInterface>hardware_interface/EffortJointInterface</hardwareInterface>
    </joint>
  </transmission>
  <link name="left_wheel_link">
    <inertial>
      <origin rpy="0 0 0" xyz="0 0 0"/>
      <mass value="8.0"/>
      <inertia ixx="0.002" ixy="0.0" ixz="0.0" iyy="0.002" iyz="0.0" izz="0.003"/>
    </inertial>
    <visual>
      <geometry>
        <cylinder length="0.096" radius="0.1016"/>
      </geometry>
      <material name="red"/>
    </visual>
    <collision>
      <geometry>
        <cylinder length="0.096" radius="0.1016"/>
      </geometry>
    </collision>
  </link>
  <gazebo reference="left_wheel_link">
    <material>Gazebo/Red</material>
    <mu1 value="0.8"/>
    <mu2 value="0.8"/>
    <kp value="10000"/>
    <kd value="1000"/>
  </gazebo>
  <joint name="right_wheel_joint" type="continuous">
    <origin rpy="-1.5707963267948966 0 0" xyz="0 -0.28485 0.1016"/>
    <parent link="base_link"/>
    <child link="right_wheel_link"/>
    <axis xyz="0 0 1"/>
    <limit effort="20.4" velocity="20.0"/>
    <dynamics damping="0.1"/>
  </joint>
  <transmission name="right_wheel_trans" type="SimpleTransmission">
    <type>transmission_interface/SimpleTransmission</type>
    <actuator name="right_wheel_motor">
      <mechanicalReduction>1</mechanicalReduction>
    </actuator>
    <joint name="right_wheel_joint">
      <hardwareInterface>hardware_interface/EffortJointInterface</hardwareInterface>
    </joint>
  </transmission>
  <link name="right_wheel_link">
    <inertial>
      <origin rpy="0 0 0" xyz="0 0 0"/>
      <mass value="8.0"/>
      <inertia ixx="0.002" ixy="0.0" ixz="0.0" iyy="0.002" iyz="0.0" izz="0.003"/>
    </inertial>
    <visual>
      <geometry>
        <cylinder length="0.096" radius="0.1016"/>
      </geometry>
      <material name="red"/>
    </visual>
    <collision>
      <geometry>
        <cylinder length="0.096" radius="0.1016"/>
      </geometry>
    </collision>
  </link>
  <gazebo reference="right_wheel_link">
    <material>Gazebo/Red</material>
    <mu1 value="0.8"/>
    <mu2 value="0.8"/>
    <kp value="10000"/>
    <kd value="1000"/>
  </gazebo>
  <joint name="front_left_caster_joint" type="fixed">
    <origin rpy="-1.5707963267948966 0 0" xyz=" 0.254  0.158 0.0375"/>
    <parent link="base_link"/>
    <child link="front_left_caster_link"/>
    <axis xyz="0 0 1"/>
  </joint>
  <link name="front_left_caster_link">
    <visual>
      <geometry>
        <sphere radius="0.0375"/>
      </geometry>
      <material name="blue"/>
    </visual>
    <collision>
      <origin rpy="0 0 0" xyz="0 0 0"/>
      <geometry>
        <sphere radius="0.0375"/>
      </geometry>
    </collision>
  </link>
  <gazebo reference="front_left_caster">
    <material>Gazebo/Blue</material>
    <mu1 value="0"/>
    <mu2 value="0"/>
  </gazebo>
  <joint name="front_right_caster_joint" type="fixed">
    <origin rpy="-1.5707963267948966 0 0" xyz=" 0.254 -0.158 0.0375"/>
    <parent link="base_link"/>
    <child link="front_right_caster_link"/>
    <axis xyz="0 0 1"/>
  </joint>
  <link name="front_right_caster_link">
    <visual>
      <geometry>
        <sphere radius="0.0375"/>
      </geometry>
      <material name="blue"/>
    </visual>
    <collision>
      <origin rpy="0 0 0" xyz="0 0 0"/>
      <geometry>
        <sphere radius="0.0375"/>
      </geometry>
    </collision>
  </link>
  <gazebo reference="front_right_caster">
    <material>Gazebo/Blue</material>
    <mu1 value="0"/>
    <mu2 value="0"/>
  </gazebo>
  <joint name="rear_left_caster_joint" type="fixed">
    <origin rpy="-1.5707963267948966 0 0" xyz="-0.254  0.254 0.0375"/>
    <parent link="base_link"/>
    <child link="rear_left_caster_link"/>
    <axis xyz="0 0 1"/>
  </joint>
  <link name="rear_left_caster_link">
    <visual>
      <geometry>
        <sphere radius="0.0375"/>
      </geometry>
      <material name="blue"/>
    </visual>
    <collision>
      <origin rpy="0 0 0" xyz="0 0 0"/>
      <geometry>
        <sphere radius="0.0375"/>
      </geometry>
    </collision>
  </link>
  <gazebo reference="rear_left_caster">
    <material>Gazebo/Blue</material>
    <mu1 value="0"/>
    <mu2 value="0"/>
  </gazebo>
  <joint name="rear_right_caster_joint" type="fixed">
    <origin rpy="-1.5707963267948966 0 0" xyz="-0.254 -0.254 0.0375"/>
    <parent link="base_link"/>
    <child link="rear_right_caster_link"/>
    <axis xyz="0 0 1"/>
  </joint>
  <link name="rear_right_caster_link">
    <visual>
      <geometry>
        <sphere radius="0.0375"/>
      </geometry>
      <material name="blue"/>
    </visual>
    <collision>
      <origin rpy="0 0 0" xyz="0 0 0"/>
      <geometry>
        <sphere radius="0.0375"/>
      </geometry>
    </collision>
  </link>
  <gazebo reference="rear_right_caster">
    <material>Gazebo/Blue</material>
    <mu1 value="0"/>
    <mu2 value="0"/>
  </gazebo>
  <joint name="front_joint" type="fixed">
    <parent link="base_link"/>
    <child link="front_link"/>
    <origin rpy="0 0 0" xyz=" 0.275   0    0.200"/>
  </joint>
  <link name="front_link">
    <visual>
      <origin rpy="0 0 0" xyz="0 0 0"/>
      <geometry>
        <cylinder length="0.07" radius="0.0213"/>
      </geometry>
      <material name="red"/>
    </visual>
    <collision>
      <origin rpy="0 0 0" xyz="0 0 0"/>
      <geometry>
        <cylinder length="0.07" radius="0.0213"/>
      </geometry>
    </collision>
  </link>
  <gazebo reference="front_link">
    <material>Gazebo/Red</material>
    <sensor name="front" type="ray">
      <pose>0 0 0 0 0 0</pose>
      <visualize>true</visualize>
      <update_rate>40</update_rate>
      <ray>
        <scan>
          <horizontal>
            <samples>1080</samples>
            <resolution>1</resolution>
            <min_angle>-2.356194490192345</min_angle>
            <max_angle>2.356194490192345</max_angle>
          </horizontal>
        </scan>
        <range>
          <min>0.2</min>
          <max>30.0</max>
          <resolution>0.25</resolution>
        </range>
        <noise>
          <type>gaussian</type>
          <mean>0.0</mean>
          <stddev>0.01</stddev>
        </noise>
      </ray>
      <plugin filename="libgazebo_ros_laser.so" name="gazebo_ros_lidar_controller">
        <topicName>/scan_front</topicName>
        <frameName>laser_front</frameName>
      </plugin>
    </sensor>
  </gazebo>
  <joint name="left_joint" type="fixed">
    <parent link="base_link"/>
    <child link="left_link"/>
    <origin rpy="0 0 3.141592653589793" xyz="-0.317   0    0.200"/>
  </joint>
  <link name="left_link">
    <visual>
      <origin rpy="0 0 0" xyz="0 0 0"/>
      <geometry>
        <cylinder length="0.07" radius="0.0213"/>
      </geometry>
      <material name="red"/>
    </visual>
    <collision>
      <origin rpy="0 0 0" xyz="0 0 0"/>
      <geometry>
        <cylinder length="0.07" radius="0.0213"/>
      </geometry>
    </collision>
  </link>
  <gazebo reference="left_link">
    <material>Gazebo/Red</material>
    <sensor name="left" type="ray">
      <pose>0 0 0 0 0 0</pose>
      <visualize>true</visualize>
      <update_rate>40</update_rate>
      <ray>
        <scan>
          <horizontal>
            <samples>1080</samples>
            <resolution>1</resolution>
            <min_angle>-2.356194490192345</min_angle>
            <max_angle>2.356194490192345</max_angle>
          </horizontal>
        </scan>
        <range>
          <min>0.2</min>
          <max>30.0</max>
          <resolution>0.25</resolution>
        </range>
        <noise>
          <type>gaussian</type>
          <mean>0.0</mean>
          <stddev>0.01</stddev>
        </noise>
      </ray>
      <plugin filename="libgazebo_ros_laser.so" name="gazebo_ros_lidar_controller">
        <topicName>/scan_rear</topicName>
        <frameName>laser_scan_rear</frameName>
      </plugin>
    </sensor>
  </gazebo>
  <joint name="front_left_joint" type="fixed">
    <parent link="base_link"/>
    <child link="front_left_link"/>
    <origin rpy="0 0 0" xyz=" 0.294  0.045 0.05"/>
  </joint>
  <link name="front_left_link">
    <visual>
      <origin rpy="0 1.5707963267948966 0" xyz="0 0 0"/>
      <geometry>
        <cylinder length="0.008" radius="0.008"/>
      </geometry>
      <material name="red"/>
    </visual>
    <collision>
      <origin rpy="0 1.5707963267948966 0" xyz="0 0 0"/>
      <geometry>
        <cylinder length="0.008" radius="0.008"/>
      </geometry>
    </collision>
  </link>
  <gazebo reference="front_left_link">
    <material>Gazebo/Red</material>
    <sensor name="front_left" type="ray">
      <pose>0 0 0 0 0 0</pose>
      <visualize>true</visualize>
      <update_rate>10</update_rate>
      <ray>
        <scan>
          <horizontal>
            <samples>10</samples>
            <resolution>1</resolution>
            <min_angle>-0.14835</min_angle>
            <max_angle>0.14835</max_angle>
          </horizontal>
          <vertical>
            <samples>10</samples>
            <resolution>1</resolution>
            <min_angle>-0.14835</min_angle>
            <max_angle>0.14835</max_angle>
          </vertical>
        </scan>
        <range>
          <min>0.01</min>
          <max>2.0</max>
          <resolution>0.02</resolution>
        </range>
      </ray>
      <plugin filename="libgazebo_ros_range.so" name="gazebo_ros_range">
        <gaussianNoise>0.005</gaussianNoise>
        <alwaysOn>true</alwaysOn>
        <updateRate>10</updateRate>
        <topicName>/uss3</topicName>
        <frameName>base_link</frameName>
        <radiation>ultrasound</radiation>
        <fov>0.2967</fov>
      </plugin>
    </sensor>
  </gazebo>
  <joint name="front_right_joint" type="fixed">
    <parent link="base_link"/>
    <child link="front_right_link"/>
    <origin rpy="0 0 0" xyz=" 0.294 -0.045 0.05"/>
  </joint>
  <link name="front_right_link">
    <visual>
      <origin rpy="0 1.5707963267948966 0" xyz="0 0 0"/>
      <geometry>
        <cylinder length="0.008" radius="0.008"/>
      </geometry>
      <material name="red"/>
    </visual>
    <collision>
      <origin rpy="0 1.5707963267948966 0" xyz="0 0 0"/>
      <geometry>
        <cylinder length="0.008" radius="0.008"/>
      </geometry>
    </collision>
  </link>
  <gazebo reference="front_right_link">
    <material>Gazebo/Red</material>
    <sensor name="front_right" type="ray">
      <pose>0 0 0 0 0 0</pose>
      <visualize>true</visualize>
      <update_rate>10</update_rate>
      <ray>
        <scan>
          <horizontal>
            <samples>10</samples>
            <resolution>1</resolution>
            <min_angle>-0.14835</min_angle>
            <max_angle>0.14835</max_angle>
          </horizontal>
          <vertical>
            <samples>10</samples>
            <resolution>1</resolution>
            <min_angle>-0.14835</min_angle>
            <max_angle>0.14835</max_angle>
          </vertical>
        </scan>
        <range>
          <min>0.01</min>
          <max>2.0</max>
          <resolution>0.02</resolution>
        </range>
      </ray>
      <plugin filename="libgazebo_ros_range.so" name="gazebo_ros_range">
        <gaussianNoise>0.005</gaussianNoise>
        <alwaysOn>true</alwaysOn>
        <updateRate>10</updateRate>
        <topicName>/uss2</topicName>
        <frameName>base_link</frameName>
        <radiation>ultrasound</radiation>
        <fov>0.2967</fov>
      </plugin>
    </sensor>
  </gazebo>
  <joint name="rear_left_joint" type="fixed">
    <parent link="base_link"/>
    <child link="rear_left_link"/>
    <origin rpy="0 0 3.141592653589793" xyz="-0.304  0.045 0.05"/>
  </joint>
  <link name="rear_left_link">
    <visual>
      <origin rpy="0 1.5707963267948966 0" xyz="0 0 0"/>
      <geometry>
        <cylinder length="0.008" radius="0.008"/>
      </geometry>
      <material name="red"/>
    </visual>
    <collision>
      <origin rpy="0 1.5707963267948966 0" xyz="0 0 0"/>
      <geometry>
        <cylinder length="0.008" radius="0.008"/>
      </geometry>
    </collision>
  </link>
  <gazebo reference="rear_left_link">
    <material>Gazebo/Red</material>
    <sensor name="rear_left" type="ray">
      <pose>0 0 0 0 0 0</pose>
      <visualize>true</visualize>
      <update_rate>10</update_rate>
      <ray>
        <scan>
          <horizontal>
            <samples>10</samples>
            <resolution>1</resolution>
            <min_angle>-0.14835</min_angle>
            <max_angle>0.14835</max_angle>
          </horizontal>
          <vertical>
            <samples>10</samples>
            <resolution>1</resolution>
            <min_angle>-0.14835</min_angle>
            <max_angle>0.14835</max_angle>
          </vertical>
        </scan>
        <range>
          <min>0.01</min>
          <max>2.0</max>
          <resolution>0.02</resolution>
        </range>
      </ray>
      <plugin filename="libgazebo_ros_range.so" name="gazebo_ros_range">
        <gaussianNoise>0.005</gaussianNoise>
        <alwaysOn>true</alwaysOn>
        <updateRate>10</updateRate>
        <topicName>/uss0</topicName>
        <frameName>base_link</frameName>
        <radiation>ultrasound</radiation>
        <fov>0.2967</fov>
      </plugin>
    </sensor>
  </gazebo>
  <joint name="rear_right_joint" type="fixed">
    <parent link="base_link"/>
    <child link="rear_right_link"/>
    <origin rpy="0 0 3.141592653589793" xyz="-0.304 -0.045 0.05"/>
  </joint>
  <link name="rear_right_link">
    <visual>
      <origin rpy="0 1.5707963267948966 0" xyz="0 0 0"/>
      <geometry>
        <cylinder length="0.008" radius="0.008"/>
      </geometry>
      <material name="red"/>
    </visual>
    <collision>
      <origin rpy="0 1.5707963267948966 0" xyz="0 0 0"/>
      <geometry>
        <cylinder length="0.008" radius="0.008"/>
      </geometry>
    </collision>
  </link>
  <gazebo reference="rear_right_link">
    <material>Gazebo/Red</material>
    <sensor name="rear_right" type="ray">
      <pose>0 0 0 0 0 0</pose>
      <visualize>true</visualize>
      <update_rate>10</update_rate>
      <ray>
        <scan>
          <horizontal>
            <samples>10</samples>
            <resolution>1</resolution>
            <min_angle>-0.14835</min_angle>
            <max_angle>0.14835</max_angle>
          </horizontal>
          <vertical>
            <samples>10</samples>
            <resolution>1</resolution>
            <min_angle>-0.14835</min_angle>
            <max_angle>0.14835</max_angle>
          </vertical>
        </scan>
        <range>
          <min>0.01</min>
          <max>2.0</max>
          <resolution>0.02</resolution>
        </range>
      </ray>
      <plugin filename="libgazebo_ros_range.so" name="gazebo_ros_range">
        <gaussianNoise>0.005</gaussianNoise>
        <alwaysOn>true</alwaysOn>
        <updateRate>10</updateRate>
        <topicName>/uss1</topicName>
        <frameName>base_link</frameName>
        <radiation>ultrasound</radiation>
        <fov>0.2967</fov>
      </plugin>
    </sensor>
  </gazebo>
  <joint name="front_realsense_joint" type="fixed">
    <parent link="base_link"/>
    <child link="front_realsense_link"/>
    <origin rpy="0 0 0" xyz=" 0.309 0 0.1"/>
  </joint>
  <link name="front_realsense_link">
    <visual>
      <origin rpy="0 -0.6108652381980153 0" xyz="0 0 0"/>
      <geometry>
        <box size="0.025 0.085 0.02"/>
      </geometry>
      <material name="red"/>
    </visual>
    <collision>
      <origin rpy="0 -0.6108652381980153 0" xyz="0 0 0"/>
      <geometry>
        <box size="0.025 0.085 0.02"/>
      </geometry>
    </collision>
  </link>
  <gazebo reference="front_realsense_link">
    <self_collide>0</self_collide>
    <enable_wind>0</enable_wind>
    <kinematic>0</kinematic>
    <gravity>1</gravity>
    <!--<mu>1</mu>-->
    <mu2>1</mu2>
    <fdir1>0 0 0</fdir1>
    <!--<slip1>0</slip1>
      <slip2>0</slip2>-->
    <kp>1e+13</kp>
    <kd>1</kd>
    <!--<max_vel>0.01</max_vel>
      <min_depth>0</min_depth>-->
    <sensor name="front_cameracolor" type="camera">
      <camera name="front_camera">
        <horizontal_fov>1.2112585008840648</horizontal_fov>
        <image>
          <width>1920</width>
          <height>1080</height>
          <format>RGB_INT8</format>
        </image>
        <clip>
          <near>0.1</near>
          <far>100</far>
        </clip>
        <noise>
          <type>gaussian</type>
          <mean>0.0</mean>
          <stddev>0.007</stddev>
        </noise>
      </camera>
      <always_on>1</always_on>
      <update_rate>30</update_rate>
      <visualize>1</visualize>
    </sensor>
    <sensor name="front_cameraired1" type="camera">
      <camera name="front_camera">
        <horizontal_fov>1.4870205226991688</horizontal_fov>
        <image>
          <width>1280</width>
          <height>720</height>
          <format>L_INT8</format>
        </image>
        <clip>
          <near>0.1</near>
          <far>100</far>
        </clip>
        <noise>
          <type>gaussian</type>
          <mean>0.0</mean>
          <stddev>0.05</stddev>
        </noise>
      </camera>
      <always_on>1</always_on>
      <update_rate>90</update_rate>
      <visualize>0</visualize>
    </sensor>
    <sensor name="front_cameraired2" type="camera">
      <camera name="front_camera">
        <horizontal_fov>1.4870205226991688</horizontal_fov>
        <image>
          <width>1280</width>
          <height>720</height>
          <format>L_INT8</format>
        </image>
        <clip>
          <near>0.1</near>
          <far>100</far>
        </clip>
        <noise>
          <type>gaussian</type>
          <mean>0.0</mean>
          <stddev>0.05</stddev>
        </noise>
      </camera>
      <always_on>1</always_on>
      <update_rate>90</update_rate>
      <visualize>0</visualize>
    </sensor>
    <sensor name="front_cameradepth" type="depth">
      <camera name="front_camera">
        <horizontal_fov>1.4870205226991688</horizontal_fov>
        <image>
          <width>1280</width>
          <height>720</height>
        </image>
        <clip>
          <near>0.1</near>
          <far>100</far>
        </clip>
        <noise>
          <type>gaussian</type>
          <mean>0.0</mean>
          <stddev>0.100</stddev>
        </noise>
      </camera>
      <always_on>1</always_on>
      <update_rate>90</update_rate>
      <visualize>0</visualize>
    </sensor>
  </gazebo>
  <gazebo>
    <plugin filename="librealsense_gazebo_plugin.so" name="front_realsense_realsense">
      <prefix>front_camera</prefix>
      <depthUpdateRate>60.0</depthUpdateRate>
      <colorUpdateRate>60.0</colorUpdateRate>
      <infraredUpdateRate>60.0</infraredUpdateRate>
      <depthTopicName>depth/image_raw</depthTopicName>
      <depthCameraInfoTopicName>depth/camera_info</depthCameraInfoTopicName>
      <colorTopicName>color/image_raw</colorTopicName>
      <colorCameraInfoTopicName>color/camera_info</colorCameraInfoTopicName>
      <infrared1TopicName>infra1/image_raw</infrared1TopicName>
      <infrared1CameraInfoTopicName>infra1/camera_info</infrared1CameraInfoTopicName>
      <infrared2TopicName>infra2/image_raw</infrared2TopicName>
      <infrared2CameraInfoTopicName>infra2/camera_info</infrared2CameraInfoTopicName>
      <colorOpticalframeName>base_link</colorOpticalframeName>
      <depthOpticalframeName>base_link</depthOpticalframeName>
      <infrared1OpticalframeName>base_link</infrared1OpticalframeName>
      <infrared2OpticalframeName>base_link</infrared2OpticalframeName>
      <rangeMinDepth>0.2</rangeMinDepth>
      <rangeMaxDepth>10.0</rangeMaxDepth>
      <pointCloud>false</pointCloud>
      <pointCloudTopicName>depth/points</pointCloudTopicName>
      <pointCloudCutoff>0.5</pointCloudCutoff>
    </plugin>
  </gazebo>
  <joint name="rear_realsense_joint" type="fixed">
    <parent link="base_link"/>
    <child link="rear_realsense_link"/>
    <origin rpy="0 0 3.141592653589793" xyz="-0.295 0 0.094"/>
  </joint>
  <link name="rear_realsense_link">
    <visual>
      <origin rpy="0 -0.6108652381980153 0" xyz="0 0 0"/>
      <geometry>
        <box size="0.025 0.085 0.02"/>
      </geometry>
      <material name="red"/>
    </visual>
    <collision>
      <origin rpy="0 -0.6108652381980153 0" xyz="0 0 0"/>
      <geometry>
        <box size="0.025 0.085 0.02"/>
      </geometry>
    </collision>
  </link>
  <gazebo reference="rear_realsense_link">
    <self_collide>0</self_collide>
    <enable_wind>0</enable_wind>
    <kinematic>0</kinematic>
    <gravity>1</gravity>
    <!--<mu>1</mu>-->
    <mu2>1</mu2>
    <fdir1>0 0 0</fdir1>
    <!--<slip1>0</slip1>
      <slip2>0</slip2>-->
    <kp>1e+13</kp>
    <kd>1</kd>
    <!--<max_vel>0.01</max_vel>
      <min_depth>0</min_depth>-->
    <sensor name="rear_cameracolor" type="camera">
      <camera name="rear_camera">
        <horizontal_fov>1.2112585008840648</horizontal_fov>
        <image>
          <width>1920</width>
          <height>1080</height>
          <format>RGB_INT8</format>
        </image>
        <clip>
          <near>0.1</near>
          <far>100</far>
        </clip>
        <noise>
          <type>gaussian</type>
          <mean>0.0</mean>
          <stddev>0.007</stddev>
        </noise>
      </camera>
      <always_on>1</always_on>
      <update_rate>30</update_rate>
      <visualize>1</visualize>
    </sensor>
    <sensor name="rear_cameraired1" type="camera">
      <camera name="rear_camera">
        <horizontal_fov>1.4870205226991688</horizontal_fov>
        <image>
          <width>1280</width>
          <height>720</height>
          <format>L_INT8</format>
        </image>
        <clip>
          <near>0.1</near>
          <far>100</far>
        </clip>
        <noise>
          <type>gaussian</type>
          <mean>0.0</mean>
          <stddev>0.05</stddev>
        </noise>
      </camera>
      <always_on>1</always_on>
      <update_rate>90</update_rate>
      <visualize>0</visualize>
    </sensor>
    <sensor name="rear_cameraired2" type="camera">
      <camera name="rear_camera">
        <horizontal_fov>1.4870205226991688</horizontal_fov>
        <image>
          <width>1280</width>
          <height>720</height>
          <format>L_INT8</format>
        </image>
        <clip>
          <near>0.1</near>
          <far>100</far>
        </clip>
        <noise>
          <type>gaussian</type>
          <mean>0.0</mean>
          <stddev>0.05</stddev>
        </noise>
      </camera>
      <always_on>1</always_on>
      <update_rate>90</update_rate>
      <visualize>0</visualize>
    </sensor>
    <sensor name="rear_cameradepth" type="depth">
      <camera name="rear_camera">
        <horizontal_fov>1.4870205226991688</horizontal_fov>
        <image>
          <width>1280</width>
          <height>720</height>
        </image>
        <clip>
          <near>0.1</near>
          <far>100</far>
        </clip>
        <noise>
          <type>gaussian</type>
          <mean>0.0</mean>
          <stddev>0.100</stddev>
        </noise>
      </camera>
      <always_on>1</always_on>
      <update_rate>90</update_rate>
      <visualize>0</visualize>
    </sensor>
  </gazebo>
  <gazebo>
    <plugin filename="librealsense_gazebo_plugin.so" name="rear_realsense_realsense">
      <prefix>rear_camera</prefix>
      <depthUpdateRate>60.0</depthUpdateRate>
      <colorUpdateRate>60.0</colorUpdateRate>
      <infraredUpdateRate>60.0</infraredUpdateRate>
      <depthTopicName>depth/image_raw</depthTopicName>
      <depthCameraInfoTopicName>depth/camera_info</depthCameraInfoTopicName>
      <colorTopicName>color/image_raw</colorTopicName>
      <colorCameraInfoTopicName>color/camera_info</colorCameraInfoTopicName>
      <infrared1TopicName>infra1/image_raw</infrared1TopicName>
      <infrared1CameraInfoTopicName>infra1/camera_info</infrared1CameraInfoTopicName>
      <infrared2TopicName>infra2/image_raw</infrared2TopicName>
      <infrared2CameraInfoTopicName>infra2/camera_info</infrared2CameraInfoTopicName>
      <colorOpticalframeName>base_link</colorOpticalframeName>
      <depthOpticalframeName>base_link</depthOpticalframeName>
      <infrared1OpticalframeName>base_link</infrared1OpticalframeName>
      <infrared2OpticalframeName>base_link</infrared2OpticalframeName>
      <rangeMinDepth>0.2</rangeMinDepth>
      <rangeMaxDepth>10.0</rangeMaxDepth>
      <pointCloud>false</pointCloud>
      <pointCloudTopicName>depth/points</pointCloudTopicName>
      <pointCloudCutoff>0.5</pointCloudCutoff>
    </plugin>
  </gazebo>
  <joint name="act0_joint" type="prismatic">
    <parent link="base_link"/>
    <child link="act0_link"/>
    <origin rpy="0 0 0" xyz=" 0.136 -0.258 0.18825"/>
    <axis xyz="0 0 1"/>
    <limit effort="0.1" lower="0.0" upper="0.05" velocity="0.1"/>
  </joint>
  <transmission name="act0_transmission" type="SimpleTransmission">
    <type>transmission_interface/SimpleTransmission</type>
    <actuator name="act0_joint">
      <mechanicalReduction>1</mechanicalReduction>
    </actuator>
    <joint name="act0_joint">
      <hardwareInterface>hardware_interface/PositionJointInterface</hardwareInterface>
    </joint>
  </transmission>
  <link name="act0_link">
    <visual>
      <origin rpy="0 0 0" xyz="0 0 0"/>
      <geometry>
        <cylinder length="0.1365" radius="0.01"/>
      </geometry>
      <material name="magenta"/>
    </visual>
    <collision>
      <origin rpy="0 0 0" xyz="0 0 0"/>
      <geometry>
        <cylinder length="0.1365" radius="0.01"/>
      </geometry>
    </collision>
    <inertial>
      <origin rpy="0 0 0" xyz="0 0 0"/>
      <mass value="0.1"/>
      <inertia ixx="0.001" ixy="0.0" ixz="0.0" iyy="0.001" iyz="0.0" izz="0.001"/>
    </inertial>
  </link>
  <gazebo reference="act0_link">
    <material>Gazebo/Green</material>
    <visualize>true</visualize>
  </gazebo>
  <joint name="act1_joint" type="prismatic">
    <parent link="base_link"/>
    <child link="act1_link"/>
    <origin rpy="0 0 0" xyz=" 0.135  0.258 0.18825"/>
    <axis xyz="0 0 1"/>
    <limit effort="0.1" lower="0.0" upper="0.05" velocity="0.1"/>
  </joint>
  <transmission name="act1_transmission" type="SimpleTransmission">
    <type>transmission_interface/SimpleTransmission</type>
    <actuator name="act1_joint">
      <mechanicalReduction>1</mechanicalReduction>
    </actuator>
    <joint name="act1_joint">
      <hardwareInterface>hardware_interface/PositionJointInterface</hardwareInterface>
    </joint>
  </transmission>
  <link name="act1_link">
    <visual>
      <origin rpy="0 0 0" xyz="0 0 0"/>
      <geometry>
        <cylinder length="0.1365" radius="0.01"/>
      </geometry>
      <material name="magenta"/>
    </visual>
    <collision>
      <origin rpy="0 0 0" xyz="0 0 0"/>
      <geometry>
        <cylinder length="0.1365" radius="0.01"/>
      </geometry>
    </collision>
    <inertial>
      <origin rpy="0 0 0" xyz="0 0 0"/>
      <mass value="0.1"/>
      <inertia ixx="0.001" ixy="0.0" ixz="0.0" iyy="0.001" iyz="0.0" izz="0.001"/>
    </inertial>
  </link>
  <gazebo reference="act1_link">
    <material>Gazebo/Green</material>
    <visualize>true</visualize>
  </gazebo>
  <joint name="act2_joint" type="prismatic">
    <parent link="base_link"/>
    <child link="act2_link"/>
    <origin rpy="0 0 0" xyz="-0.134 -0.258 0.18825"/>
    <axis xyz="0 0 1"/>
    <limit effort="0.1" lower="0.0" upper="0.05" velocity="0.1"/>
  </joint>
  <transmission name="act2_transmission" type="SimpleTransmission">
    <type>transmission_interface/SimpleTransmission</type>
    <actuator name="act2_joint">
      <mechanicalReduction>1</mechanicalReduction>
    </actuator>
    <joint name="act2_joint">
      <hardwareInterface>hardware_interface/PositionJointInterface</hardwareInterface>
    </joint>
  </transmission>
  <link name="act2_link">
    <visual>
      <origin rpy="0 0 0" xyz="0 0 0"/>
      <geometry>
        <cylinder length="0.1365" radius="0.01"/>
      </geometry>
      <material name="magenta"/>
    </visual>
    <collision>
      <origin rpy="0 0 0" xyz="0 0 0"/>
      <geometry>
        <cylinder length="0.1365" radius="0.01"/>
      </geometry>
    </collision>
    <inertial>
      <origin rpy="0 0 0" xyz="0 0 0"/>
      <mass value="0.1"/>
      <inertia ixx="0.001" ixy="0.0" ixz="0.0" iyy="0.001" iyz="0.0" izz="0.001"/>
    </inertial>
  </link>
  <gazebo reference="act2_link">
    <material>Gazebo/Green</material>
    <visualize>true</visualize>
  </gazebo>
  <joint name="act3_joint" type="prismatic">
    <parent link="base_link"/>
    <child link="act3_link"/>
    <origin rpy="0 0 0" xyz="-0.134  0.258 0.18825"/>
    <axis xyz="0 0 1"/>
    <limit effort="0.1" lower="0.0" upper="0.05" velocity="0.1"/>
  </joint>
  <transmission name="act3_transmission" type="SimpleTransmission">
    <type>transmission_interface/SimpleTransmission</type>
    <actuator name="act3_joint">
      <mechanicalReduction>1</mechanicalReduction>
    </actuator>
    <joint name="act3_joint">
      <hardwareInterface>hardware_interface/PositionJointInterface</hardwareInterface>
    </joint>
  </transmission>
  <link name="act3_link">
    <visual>
      <origin rpy="0 0 0" xyz="0 0 0"/>
      <geometry>
        <cylinder length="0.1365" radius="0.01"/>
      </geometry>
      <material name="magenta"/>
    </visual>
    <collision>
      <origin rpy="0 0 0" xyz="0 0 0"/>
      <geometry>
        <cylinder length="0.1365" radius="0.01"/>
      </geometry>
    </collision>
    <inertial>
      <origin rpy="0 0 0" xyz="0 0 0"/>
      <mass value="0.1"/>
      <inertia ixx="0.001" ixy="0.0" ixz="0.0" iyy="0.001" iyz="0.0" izz="0.001"/>
    </inertial>
  </link>
  <gazebo reference="act3_link">
    <material>Gazebo/Green</material>
    <visualize>true</visualize>
  </gazebo>
  <joint name="pgv_joint" type="fixed">
    <parent link="base_link"/>
    <child link="pgv_link"/>
    <origin rpy="0 0 0" xyz="0 0 0.125"/>
  </joint>
  <link name="pgv_link">
    <visual>
      <origin rpy="0 0 0" xyz="0.15 0 0"/>
      <geometry>
        <box size="0.07 0.07 0.05"/>
      </geometry>
      <material name="green"/>
    </visual>
  </link>
  <gazebo reference="pgv_link">
    <material>Gazebo/Green</material>
  </gazebo>
  <gazebo>
    <plugin filename="libgazebo_ros_control.so" name="gazebo_ros_control">
      <robotNamespace>/v4_robot</robotNamespace>
      <robotSimType>gazebo_ros_control/DefaultRobotHWSim</robotSimType>
      <legacyModeNS>true</legacyModeNS>
    </plugin>
  </gazebo>
</robot>

